Traceback (most recent call last):
  File "C:\Users\LENOVO\AppData\Local\Programs\Python\Python310\lib\site-packages\jupyter_cache\executors\utils.py", line 58, in single_nb_execution
    executenb(
  File "C:\Users\LENOVO\AppData\Local\Programs\Python\Python310\lib\site-packages\nbclient\client.py", line 1265, in execute
    return NotebookClient(nb=nb, resources=resources, km=km, **kwargs).execute()
  File "C:\Users\LENOVO\AppData\Local\Programs\Python\Python310\lib\site-packages\jupyter_core\utils\__init__.py", line 166, in wrapped
    return loop.run_until_complete(inner)
  File "C:\Users\LENOVO\AppData\Local\Programs\Python\Python310\lib\asyncio\base_events.py", line 649, in run_until_complete
    return future.result()
  File "C:\Users\LENOVO\AppData\Local\Programs\Python\Python310\lib\site-packages\nbclient\client.py", line 703, in async_execute
    await self.async_execute_cell(
  File "C:\Users\LENOVO\AppData\Local\Programs\Python\Python310\lib\site-packages\nbclient\client.py", line 1021, in async_execute_cell
    await self._check_raise_for_error(cell, cell_index, exec_reply)
  File "C:\Users\LENOVO\AppData\Local\Programs\Python\Python310\lib\site-packages\nbclient\client.py", line 915, in _check_raise_for_error
    raise CellExecutionError.from_cell_and_msg(cell, exec_reply_content)
nbclient.exceptions.CellExecutionError: An error occurred while executing the following cell:
------------------
print(tree.export_graphviz(clf_train, None))
dot_data = tree.export_graphviz(clf_train, out_file=None, feature_names=list(one_hot_data.columns.values), 
                                class_names=['Not_Play', 'Play'], rounded=True, filled=True) 
graph = pydotplus.graph_from_dot_data(dot_data)
Image(graph.create_png())
------------------

[1;31m---------------------------------------------------------------------------[0m
[1;31mInvocationException[0m                       Traceback (most recent call last)
Cell [1;32mIn[5], line 5[0m
[0;32m      2[0m dot_data [38;5;241m=[39m tree[38;5;241m.[39mexport_graphviz(clf_train, out_file[38;5;241m=[39m[38;5;28;01mNone[39;00m, feature_names[38;5;241m=[39m[38;5;28mlist[39m(one_hot_data[38;5;241m.[39mcolumns[38;5;241m.[39mvalues), 
[0;32m      3[0m                                 class_names[38;5;241m=[39m[[38;5;124m'[39m[38;5;124mNot_Play[39m[38;5;124m'[39m, [38;5;124m'[39m[38;5;124mPlay[39m[38;5;124m'[39m], rounded[38;5;241m=[39m[38;5;28;01mTrue[39;00m, filled[38;5;241m=[39m[38;5;28;01mTrue[39;00m) 
[0;32m      4[0m graph [38;5;241m=[39m pydotplus[38;5;241m.[39mgraph_from_dot_data(dot_data)
[1;32m----> 5[0m Image([43mgraph[49m[38;5;241;43m.[39;49m[43mcreate_png[49m[43m([49m[43m)[49m)

File [1;32m~\AppData\Local\Programs\Python\Python310\lib\site-packages\pydotplus\graphviz.py:1797[0m, in [0;36mDot.__init__.<locals>.<lambda>[1;34m(f, prog)[0m
[0;32m   1792[0m [38;5;66;03m# Automatically creates all the methods enabling the creation[39;00m
[0;32m   1793[0m [38;5;66;03m# of output in any of the supported formats.[39;00m
[0;32m   1794[0m [38;5;28;01mfor[39;00m frmt [38;5;129;01min[39;00m [38;5;28mself[39m[38;5;241m.[39mformats:
[0;32m   1795[0m     [38;5;28mself[39m[38;5;241m.[39m[38;5;21m__setattr__[39m(
[0;32m   1796[0m         [38;5;124m'[39m[38;5;124mcreate_[39m[38;5;124m'[39m [38;5;241m+[39m frmt,
[1;32m-> 1797[0m         [38;5;28;01mlambda[39;00m f[38;5;241m=[39mfrmt, prog[38;5;241m=[39m[38;5;28mself[39m[38;5;241m.[39mprog: [38;5;28;43mself[39;49m[38;5;241;43m.[39;49m[43mcreate[49m[43m([49m[38;5;28;43mformat[39;49m[38;5;241;43m=[39;49m[43mf[49m[43m,[49m[43m [49m[43mprog[49m[38;5;241;43m=[39;49m[43mprog[49m[43m)[49m
[0;32m   1798[0m     )
[0;32m   1799[0m     f [38;5;241m=[39m [38;5;28mself[39m[38;5;241m.[39m[38;5;18m__dict__[39m[[38;5;124m'[39m[38;5;124mcreate_[39m[38;5;124m'[39m [38;5;241m+[39m frmt]
[0;32m   1800[0m     f[38;5;241m.[39m[38;5;18m__doc__[39m [38;5;241m=[39m (
[0;32m   1801[0m [38;5;250m        [39m[38;5;124;03m'''Refer to the docstring accompanying the'''[39;00m
[0;32m   1802[0m [38;5;250m        [39m[38;5;124;03m''''create' method for more information.'''[39;00m
[0;32m   1803[0m     )

File [1;32m~\AppData\Local\Programs\Python\Python310\lib\site-packages\pydotplus\graphviz.py:1959[0m, in [0;36mDot.create[1;34m(self, prog, format)[0m
[0;32m   1957[0m     [38;5;28mself[39m[38;5;241m.[39mprogs [38;5;241m=[39m find_graphviz()
[0;32m   1958[0m     [38;5;28;01mif[39;00m [38;5;28mself[39m[38;5;241m.[39mprogs [38;5;129;01mis[39;00m [38;5;28;01mNone[39;00m:
[1;32m-> 1959[0m         [38;5;28;01mraise[39;00m InvocationException(
[0;32m   1960[0m             [38;5;124m'[39m[38;5;124mGraphViz[39m[38;5;130;01m\'[39;00m[38;5;124ms executables not found[39m[38;5;124m'[39m)
[0;32m   1962[0m [38;5;28;01mif[39;00m prog [38;5;129;01mnot[39;00m [38;5;129;01min[39;00m [38;5;28mself[39m[38;5;241m.[39mprogs:
[0;32m   1963[0m     [38;5;28;01mraise[39;00m InvocationException(
[0;32m   1964[0m         [38;5;124m'[39m[38;5;124mGraphViz[39m[38;5;130;01m\'[39;00m[38;5;124ms executable [39m[38;5;124m"[39m[38;5;132;01m%s[39;00m[38;5;124m"[39m[38;5;124m not found[39m[38;5;124m'[39m [38;5;241m%[39m prog)

[1;31mInvocationException[0m: GraphViz's executables not found
InvocationException: GraphViz's executables not found

